Workbook

Sheet RiskRanges
A1: Date | B1: Ticker | C1: High | D1: Low | E1: Prior High | F1: Prior Low | G1: High Structure | H1: Low Structure | I1: Trend Signal
E2: =IF(AND(B2=B1,A2>A1),C1,"") | F2: =IF(AND(B2=B1,A2>A1),D1,"") | G2: =IF(E2="","",IF(C2>E2,"Higher High",IF(C2<E2,"Lower High","Flat"))) | H2: =IF(F2="","",IF(D2>F2,"Higher Low",IF(D2<F2,"Lower Low","Flat"))) | I2: =IF(AND(G2="Higher High",H2="Higher Low"),"Bullish",IF(AND(G2="Lower High",H2="Lower Low"),"Bearish","Mixed")) -> Mixed | O2: INDEX | P2: BUY TRADE | Q2: SELL TRADE | R2: PREV. CLOSE
E3: =IF(AND(B3=B2,A3>A2),C2,"") | F3: =IF(AND(B3=B2,A3>A2),D2,"") | G3: =IF(E3="","",IF(C3>E3,"Higher High",IF(C3<E3,"Lower High","Flat"))) | H3: =IF(F3="","",IF(D3>F3,"Higher Low",IF(D3<F3,"Lower Low","Flat"))) | I3: =IF(AND(G3="Higher High",H3="Higher Low"),"Bullish",IF(AND(G3="Lower High",H3="Lower Low"),"Bearish","Mixed")) -> Mixed | O3: UST30Y (BEARISH)
E4: =IF(AND(B4=B3,A4>A3),C3,"") | F4: =IF(AND(B4=B3,A4>A3),D3,"") | G4: =IF(E4="","",IF(C4>E4,"Higher High",IF(C4<E4,"Lower High","Flat"))) | H4: =IF(F4="","",IF(D4>F4,"Higher Low",IF(D4<F4,"Lower Low","Flat"))) | I4: =IF(AND(G4="Higher High",H4="Higher Low"),"Bullish",IF(AND(G4="Lower High",H4="Lower Low"),"Bearish","Mixed")) -> Mixed | O4: 30-Year U.S. Treasury Yield | P4: 4.75 | Q4: 4.65 | R4: 4.71
E5: =IF(AND(B5=B4,A5>A4),C4,"") | F5: =IF(AND(B5=B4,A5>A4),D4,"") | G5: =IF(E5="","",IF(C5>E5,"Higher High",IF(C5<E5,"Lower High","Flat"))) | H5: =IF(F5="","",IF(D5>F5,"Higher Low",IF(D5<F5,"Lower Low","Flat"))) | I5: =IF(AND(G5="Higher High",H5="Higher Low"),"Bullish",IF(AND(G5="Lower High",H5="Lower Low"),"Bearish","Mixed")) -> Mixed | O5: UST10Y (BEARISH)
E6: =IF(AND(B6=B5,A6>A5),C5,"") | F6: =IF(AND(B6=B5,A6>A5),D5,"") | G6: =IF(E6="","",IF(C6>E6,"Higher High",IF(C6<E6,"Lower High","Flat"))) | H6: =IF(F6="","",IF(D6>F6,"Higher Low",IF(D6<F6,"Lower Low","Flat"))) | I6: =IF(AND(G6="Higher High",H6="Higher Low"),"Bullish",IF(AND(G6="Lower High",H6="Lower Low"),"Bearish","Mixed")) -> Mixed | O6: 10-Year U.S. Treasury Yield | P6: 4.15 | Q6: 4.02 | R6: 4.07
E7: =IF(AND(B7=B6,A7>A6),C6,"") | F7: =IF(AND(B7=B6,A7>A6),D6,"") | G7: =IF(E7="","",IF(C7>E7,"Higher High",IF(C7<E7,"Lower High","Flat"))) | H7: =IF(F7="","",IF(D7>F7,"Higher Low",IF(D7<F7,"Lower Low","Flat"))) | I7: =IF(AND(G7="Higher High",H7="Higher Low"),"Bullish",IF(AND(G7="Lower High",H7="Lower Low"),"Bearish","Mixed")) -> Mixed | O7: UST2Y (BEARISH)
E8: =IF(AND(B8=B7,A8>A7),C7,"") | F8: =IF(AND(B8=B7,A8>A7),D7,"") | G8: =IF(E8="","",IF(C8>E8,"Higher High",IF(C8<E8,"Lower High","Flat"))) | H8: =IF(F8="","",IF(D8>F8,"Higher Low",IF(D8<F8,"Lower Low","Flat"))) | I8: =IF(AND(G8="Higher High",H8="Higher Low"),"Bullish",IF(AND(G8="Lower High",H8="Lower Low"),"Bearish","Mixed")) -> Mixed | O8: 2-Year U.S. Treasury Yield | P8: 3.62 | Q8: 3.49 | R8: 3.52
E9: =IF(AND(B9=B8,A9>A8),C8,"") | F9: =IF(AND(B9=B8,A9>A8),D8,"") | G9: =IF(E9="","",IF(C9>E9,"Higher High",IF(C9<E9,"Lower High","Flat"))) | H9: =IF(F9="","",IF(D9>F9,"Higher Low",IF(D9<F9,"Lower Low","Flat"))) | I9: =IF(AND(G9="Higher High",H9="Higher Low"),"Bullish",IF(AND(G9="Lower High",H9="Lower Low"),"Bearish","Mixed")) -> Mixed | O9: HYG (NEUTRAL)
E10: =IF(AND(B90=B9,A90>A9),C9,"") | F10: =IF(AND(B90=B9,A90>A9),D9,"") | G10: =IF(E10="","",IF(C10>E10,"Higher High",IF(C10<E10,"Lower High","Flat"))) | H10: =IF(F10="","",IF(D10>F10,"Higher Low",IF(D10<F10,"Lower Low","Flat"))) | I10: =IF(AND(G10="Higher High",H10="Higher Low"),"Bullish",IF(AND(G10="Lower High",H10="Lower Low"),"Bearish","Mixed")) -> Mixed | O10: High Yield | P10: 79.85 | Q10: 80.61 | R10: 80.37
E11: =IF(AND(B1010=B10,A1010>A10),C10,"") | F11: =IF(AND(B1010=B10,A1010>A10),D10,"") | G11: =IF(E11="","",IF(C11>E11,"Higher High",IF(C11<E11,"Lower High","Flat"))) | H11: =IF(F11="","",IF(D11>F11,"Higher Low",IF(D11<F11,"Lower Low","Flat"))) | I11: =IF(AND(G11="Higher High",H11="Higher Low"),"Bullish",IF(AND(G11="Lower High",H11="Lower Low"),"Bearish","Mixed")) -> Mixed | O11: LQD (BULLISH)
E12: =IF(AND(B112=B11,A112>A11),C11,"") | F12: =IF(AND(B112=B11,A112>A11),D11,"") | G12: =IF(E12="","",IF(C12>E12,"Higher High",IF(C12<E12,"Lower High","Flat"))) | H12: =IF(F12="","",IF(D12>F12,"Higher Low",IF(D12<F12,"Lower Low","Flat"))) | I12: =IF(AND(G12="Higher High",H12="Higher Low"),"Bullish",IF(AND(G12="Lower High",H12="Lower Low"),"Bearish","Mixed")) -> Mixed | O12: Investment Grade Corporate Bond ETF | P12: 110.1 | Q12: 111.6 | R12: 110.9
E13: =IF(AND(B123=B12,A123>A12),C12,"") | F13: =IF(AND(B123=B12,A123>A12),D12,"") | G13: =IF(E13="","",IF(C13>E13,"Higher High",IF(C13<E13,"Lower High","Flat"))) | H13: =IF(F13="","",IF(D13>F13,"Higher Low",IF(D13<F13,"Lower Low","Flat"))) | I13: =IF(AND(G13="Higher High",H13="Higher Low"),"Bullish",IF(AND(G13="Lower High",H13="Lower Low"),"Bearish","Mixed")) -> Mixed | O13: SPX (BULLISH)
E14: =IF(AND(B134=B13,A134>A13),C13,"") | F14: =IF(AND(B134=B13,A134>A13),D13,"") | G14: =IF(E14="","",IF(C14>E14,"Higher High",IF(C14<E14,"Lower High","Flat"))) | H14: =IF(F14="","",IF(D14>F14,"Higher Low",IF(D14<F14,"Lower Low","Flat"))) | I14: =IF(AND(G14="Higher High",H14="Higher Low"),"Bullish",IF(AND(G14="Lower High",H14="Lower Low"),"Bearish","Mixed")) -> Mixed | O14: S&P 500 | P14: 6476 | Q14: 6713 | R14: 6602
E15: =IF(AND(B145=B14,A145>A14),C14,"") | F15: =IF(AND(B145=B14,A145>A14),D14,"") | G15: =IF(E15="","",IF(C15>E15,"Higher High",IF(C15<E15,"Lower High","Flat"))) | H15: =IF(F15="","",IF(D15>F15,"Higher Low",IF(D15<F15,"Lower Low","Flat"))) | I15: =IF(AND(G15="Higher High",H15="Higher Low"),"Bullish",IF(AND(G15="Lower High",H15="Lower Low"),"Bearish","Mixed")) -> Mixed | O15: COMPQ (BEARISH)
E16: =IF(AND(B156=B15,A156>A15),C15,"") | F16: =IF(AND(B156=B15,A156>A15),D15,"") | G16: =IF(E16="","",IF(C16>E16,"Higher High",IF(C16<E16,"Lower High","Flat"))) | H16: =IF(F16="","",IF(D16>F16,"Higher Low",IF(D16<F16,"Lower Low","Flat"))) | I16: =IF(AND(G16="Higher High",H16="Higher Low"),"Bullish",IF(AND(G16="Lower High",H16="Lower Low"),"Bearish","Mixed")) -> Mixed | O16: NASDAQ Composite | P16: 21830 | Q16: 22906 | R16: 22273
E17: =IF(AND(B167=B16,A167>A16),C16,"") | F17: =IF(AND(B167=B16,A167>A16),D16,"") | G17: =IF(E17="","",IF(C17>E17,"Higher High",IF(C17<E17,"Lower High","Flat"))) | H17: =IF(F17="","",IF(D17>F17,"Higher Low",IF(D17<F17,"Lower Low","Flat"))) | I17: =IF(AND(G17="Higher High",H17="Higher Low"),"Bullish",IF(AND(G17="Lower High",H17="Lower Low"),"Bearish","Mixed")) -> Mixed | O17: RUT (BEARISH)
E18: =IF(AND(B178=B17,A178>A17),C17,"") | F18: =IF(AND(B178=B17,A178>A17),D17,"") | G18: =IF(E18="","",IF(C18>E18,"Higher High",IF(C18<E18,"Lower High","Flat"))) | H18: =IF(F18="","",IF(D18>F18,"Higher Low",IF(D18<F18,"Lower Low","Flat"))) | I18: =IF(AND(G18="Higher High",H18="Higher Low"),"Bullish",IF(AND(G18="Lower High",H18="Lower Low"),"Bearish","Mixed")) -> Mixed | O18: Russell 2000 | P18: 2278 | Q18: 2412 | R18: 2369
E19: =IF(AND(B189=B18,A189>A18),C18,"") | F19: =IF(AND(B189=B18,A189>A18),D18,"") | G19: =IF(E19="","",IF(C19>E19,"Higher High",IF(C19<E19,"Lower High","Flat"))) | H19: =IF(F19="","",IF(D19>F19,"Higher Low",IF(D19<F19,"Lower Low","Flat"))) | I19: =IF(AND(G19="Higher High",H19="Higher Low"),"Bullish",IF(AND(G19="Lower High",H19="Lower Low"),"Bearish","Mixed")) -> Mixed | O19: XLK (BEARISH)
E20: =IF(AND(B20=B19,A20>A19),C19,"") | F20: =IF(AND(B20=B19,A20>A19),D19,"") | G20: =IF(E20="","",IF(C20>E20,"Higher High",IF(C20<E20,"Lower High","Flat"))) | H20: =IF(F20="","",IF(D20>F20,"Higher Low",IF(D20<F20,"Lower Low","Flat"))) | I20: =IF(AND(G20="Higher High",H20="Higher Low"),"Bullish",IF(AND(G20="Lower High",H20="Lower Low"),"Bearish","Mixed")) -> Mixed | O20: Technology Select Sector SPDR Fund | P20: 267 | Q20: 286 | R20: 273
E21: =IF(AND(B220=B20,A220>A20),C20,"") | F21: =IF(AND(B220=B20,A220>A20),D20,"") | G21: =IF(E21="","",IF(C21>E21,"Higher High",IF(C21<E21,"Lower High","Flat"))) | H21: =IF(F21="","",IF(D21>F21,"Higher Low",IF(D21<F21,"Lower Low","Flat"))) | I21: =IF(AND(G21="Higher High",H21="Higher Low"),"Bullish",IF(AND(G21="Lower High",H21="Lower Low"),"Bearish","Mixed")) -> Mixed | O21: XLV (BULLISH)
E22: =IF(AND(B22=B21,A22>A21),C21,"") | F22: =IF(AND(B22=B21,A22>A21),D21,"") | G22: =IF(E22="","",IF(C22>E22,"Higher High",IF(C22<E22,"Lower High","Flat"))) | H22: =IF(F22="","",IF(D22>F22,"Higher Low",IF(D22<F22,"Lower Low","Flat"))) | I22: =IF(AND(G22="Higher High",H22="Higher Low"),"Bullish",IF(AND(G22="Lower High",H22="Lower Low"),"Bearish","Mixed")) -> Mixed | O22: Health Care Select Sector SPDR Fund | P22: 151 | Q22: 156 | R22: 154.61
E23: =IF(AND(B23=B22,A23>A22),C22,"") | F23: =IF(AND(B23=B22,A23>A22),D22,"") | G23: =IF(E23="","",IF(C23>E23,"Higher High",IF(C23<E23,"Lower High","Flat"))) | H23: =IF(F23="","",IF(D23>F23,"Higher Low",IF(D23<F23,"Lower Low","Flat"))) | I23: =IF(AND(G23="Higher High",H23="Higher Low"),"Bullish",IF(AND(G23="Lower High",H23="Lower Low"),"Bearish","Mixed")) -> Mixed | O23: SSEC (BEARISH)
E24: =IF(AND(B24=B23,A24>A23),C23,"") | F24: =IF(AND(B24=B23,A24>A23),D23,"") | G24: =IF(E24="","",IF(C24>E24,"Higher High",IF(C24<E24,"Lower High","Flat"))) | H24: =IF(F24="","",IF(D24>F24,"Higher Low",IF(D24<F24,"Lower Low","Flat"))) | I24: =IF(AND(G24="Higher High",H24="Higher Low"),"Bullish",IF(AND(G24="Lower High",H24="Lower Low"),"Bearish","Mixed")) -> Mixed | O24: Shanghai Composite | P24: 3806 | Q24: 3961 | R24: 3836
E25: =IF(AND(B25=B24,A25>A24),C24,"") | F25: =IF(AND(B25=B24,A25>A24),D24,"") | G25: =IF(E25="","",IF(C25>E25,"Higher High",IF(C25<E25,"Lower High","Flat"))) | H25: =IF(F25="","",IF(D25>F25,"Higher Low",IF(D25<F25,"Lower Low","Flat"))) | I25: =IF(AND(G25="Higher High",H25="Higher Low"),"Bullish",IF(AND(G25="Lower High",H25="Lower Low"),"Bearish","Mixed")) -> Mixed | O25: NIKK (NEUTRAL)
E26: =IF(AND(B26=B25,A26>A25),C25,"") | F26: =IF(AND(B26=B25,A26>A25),D25,"") | G26: =IF(E26="","",IF(C26>E26,"Higher High",IF(C26<E26,"Lower High","Flat"))) | H26: =IF(F26="","",IF(D26>F26,"Higher Low",IF(D26<F26,"Lower Low","Flat"))) | I26: =IF(AND(G26="Higher High",H26="Higher Low"),"Bullish",IF(AND(G26="Lower High",H26="Lower Low"),"Bearish","Mixed")) -> Mixed | O26: Nikkei 225 Index | P26: 48218 | Q26: 51210 | R26: 48625
E27: =IF(AND(B27=B26,A27>A26),C26,"") | F27: =IF(AND(B27=B26,A27>A26),D26,"") | G27: =IF(E27="","",IF(C27>E27,"Higher High",IF(C27<E27,"Lower High","Flat"))) | H27: =IF(F27="","",IF(D27>F27,"Higher Low",IF(D27<F27,"Lower Low","Flat"))) | I27: =IF(AND(G27="Higher High",H27="Higher Low"),"Bullish",IF(AND(G27="Lower High",H27="Lower Low"),"Bearish","Mixed")) -> Mixed | O27: DAX (BEARISH)
E28: =IF(AND(B28=B27,A28>A27),C27,"") | F28: =IF(AND(B28=B27,A28>A27),D27,"") | G28: =IF(E28="","",IF(C28>E28,"Higher High",IF(C28<E28,"Lower High","Flat"))) | H28: =IF(F28="","",IF(D28>F28,"Higher Low",IF(D28<F28,"Lower Low","Flat"))) | I28: =IF(AND(G28="Higher High",H28="Higher Low"),"Bullish",IF(AND(G28="Lower High",H28="Lower Low"),"Bearish","Mixed")) -> Mixed | O28: German DAX Composite | P28: 22708 | Q28: 23815 | R28: 23091
E29: =IF(AND(B29=B28,A29>A28),C28,"") | F29: =IF(AND(B29=B28,A29>A28),D28,"") | G29: =IF(E29="","",IF(C29>E29,"Higher High",IF(C29<E29,"Lower High","Flat"))) | H29: =IF(F29="","",IF(D29>F29,"Higher Low",IF(D29<F29,"Lower Low","Flat"))) | I29: =IF(AND(G29="Higher High",H29="Higher Low"),"Bullish",IF(AND(G29="Lower High",H29="Lower Low"),"Bearish","Mixed")) -> Mixed | O29: VIX (BULLISH)
E30: =IF(AND(B30=B29,A30>A29),C29,"") | F30: =IF(AND(B30=B29,A30>A29),D29,"") | G30: =IF(E30="","",IF(C30>E30,"Higher High",IF(C30<E30,"Lower High","Flat"))) | H30: =IF(F30="","",IF(D30>F30,"Higher Low",IF(D30<F30,"Lower Low","Flat"))) | I30: =IF(AND(G30="Higher High",H30="Higher Low"),"Bullish",IF(AND(G30="Lower High",H30="Lower Low"),"Bearish","Mixed")) -> Mixed | O30: Volatility Index | P30: 19.87 | Q30: 27.97 | R30: 23.43
E31: =IF(AND(B330=B30,A330>A30),C30,"") | F31: =IF(AND(B330=B30,A330>A30),D30,"") | G31: =IF(E31="","",IF(C31>E31,"Higher High",IF(C31<E31,"Lower High","Flat"))) | H31: =IF(F31="","",IF(D31>F31,"Higher Low",IF(D31<F31,"Lower Low","Flat"))) | I31: =IF(AND(G31="Higher High",H31="Higher Low"),"Bullish",IF(AND(G31="Lower High",H31="Lower Low"),"Bearish","Mixed")) -> Mixed | O31: USD (BULLISH)
E32: =IF(AND(B32=B31,A32>A31),C31,"") | F32: =IF(AND(B32=B31,A32>A31),D31,"") | G32: =IF(E32="","",IF(C32>E32,"Higher High",IF(C32<E32,"Lower High","Flat"))) | H32: =IF(F32="","",IF(D32>F32,"Higher Low",IF(D32<F32,"Lower Low","Flat"))) | I32: =IF(AND(G32="Higher High",H32="Higher Low"),"Bullish",IF(AND(G32="Lower High",H32="Lower Low"),"Bearish","Mixed")) -> Mixed | O32: U.S. Dollar Index | P32: 99.46 | Q32: 100.57 | R32: 100.07
E33: =IF(AND(B33=B32,A33>A32),C32,"") | F33: =IF(AND(B33=B32,A33>A32),D32,"") | G33: =IF(E33="","",IF(C33>E33,"Higher High",IF(C33<E33,"Lower High","Flat"))) | H33: =IF(F33="","",IF(D33>F33,"Higher Low",IF(D33<F33,"Lower Low","Flat"))) | I33: =IF(AND(G33="Higher High",H33="Higher Low"),"Bullish",IF(AND(G33="Lower High",H33="Lower Low"),"Bearish","Mixed")) -> Mixed | O33: EUR/USD (BEARISH)
E34: =IF(AND(B34=B33,A34>A33),C33,"") | F34: =IF(AND(B34=B33,A34>A33),D33,"") | G34: =IF(E34="","",IF(C34>E34,"Higher High",IF(C34<E34,"Lower High","Flat"))) | H34: =IF(F34="","",IF(D34>F34,"Higher Low",IF(D34<F34,"Lower Low","Flat"))) | I34: =IF(AND(G34="Higher High",H34="Higher Low"),"Bullish",IF(AND(G34="Lower High",H34="Lower Low"),"Bearish","Mixed")) -> Mixed | O34: Euro to U.S. Dollar | P34: 1.148 | Q34: 1.16 | R34: 1.154
E35: =IF(AND(B35=B34,A35>A34),C34,"") | F35: =IF(AND(B35=B34,A35>A34),D34,"") | G35: =IF(E35="","",IF(C35>E35,"Higher High",IF(C35<E35,"Lower High","Flat"))) | H35: =IF(F35="","",IF(D35>F35,"Higher Low",IF(D35<F35,"Lower Low","Flat"))) | I35: =IF(AND(G35="Higher High",H35="Higher Low"),"Bullish",IF(AND(G35="Lower High",H35="Lower Low"),"Bearish","Mixed")) -> Mixed | O35: USD/YEN (BULLISH)
E36: =IF(AND(B36=B35,A36>A35),C35,"") | F36: =IF(AND(B36=B35,A36>A35),D35,"") | G36: =IF(E36="","",IF(C36>E36,"Higher High",IF(C36<E36,"Lower High","Flat"))) | H36: =IF(F36="","",IF(D36>F36,"Higher Low",IF(D36<F36,"Lower Low","Flat"))) | I36: =IF(AND(G36="Higher High",H36="Higher Low"),"Bullish",IF(AND(G36="Lower High",H36="Lower Low"),"Bearish","Mixed")) -> Mixed | O36: U.S. Dollar to Japanese Yen | P36: 154.18 | Q36: 157.97 | R36: 156.82
E37: =IF(AND(B37=B36,A37>A36),C36,"") | F37: =IF(AND(B37=B36,A37>A36),D36,"") | G37: =IF(E37="","",IF(C37>E37,"Higher High",IF(C37<E37,"Lower High","Flat"))) | H37: =IF(F37="","",IF(D37>F37,"Higher Low",IF(D37<F37,"Lower Low","Flat"))) | I37: =IF(AND(G37="Higher High",H37="Higher Low"),"Bullish",IF(AND(G37="Lower High",H37="Lower Low"),"Bearish","Mixed")) -> Mixed | O37: GBP/USD (BEARISH)
E38: =IF(AND(B38=B37,A38>A37),C37,"") | F38: =IF(AND(B38=B37,A38>A37),D37,"") | G38: =IF(E38="","",IF(C38>E38,"Higher High",IF(C38<E38,"Lower High","Flat"))) | H38: =IF(F38="","",IF(D38>F38,"Higher Low",IF(D38<F38,"Lower Low","Flat"))) | I38: =IF(AND(G38="Higher High",H38="Higher Low"),"Bullish",IF(AND(G38="Lower High",H38="Lower Low"),"Bearish","Mixed")) -> Mixed | O38: British Pound to U.S. Dollar | P38: 1.303 | Q38: 1.319 | R38: 1.311
E39: =IF(AND(B39=B38,A39>A38),C38,"") | F39: =IF(AND(B39=B38,A39>A38),D38,"") | G39: =IF(E39="","",IF(C39>E39,"Higher High",IF(C39<E39,"Lower High","Flat"))) | H39: =IF(F39="","",IF(D39>F39,"Higher Low",IF(D39<F39,"Lower Low","Flat"))) | I39: =IF(AND(G39="Higher High",H39="Higher Low"),"Bullish",IF(AND(G39="Lower High",H39="Lower Low"),"Bearish","Mixed")) -> Mixed | O39: CAD/USD (BEARISH)
E40: =IF(AND(B40=B39,A40>A39),C39,"") | F40: =IF(AND(B40=B39,A40>A39),D39,"") | G40: =IF(E40="","",IF(C40>E40,"Higher High",IF(C40<E40,"Lower High","Flat"))) | H40: =IF(F40="","",IF(D40>F40,"Higher Low",IF(D40<F40,"Lower Low","Flat"))) | I40: =IF(AND(G40="Higher High",H40="Higher Low"),"Bullish",IF(AND(G40="Lower High",H40="Lower Low"),"Bearish","Mixed")) -> Mixed | O40: Canadian Dollar to U.S. Dollar | P40: 0.706 | Q40: 0.717 | R40: 0.708
...

Sheet Nov. 24.2025
A1: INDEX | B1: BUY TRADE | C1: SELL TRADE | D1: PREV. CLOSE
A2: UST30Y (BEARISH)
A3: 30-Year U.S. Treasury Yield | B3: 4.75 | C3: 4.65 | D3: 4.71
A4: UST10Y (BEARISH)
A5: 10-Year U.S. Treasury Yield | B5: 4.15 | C5: 4.02 | D5: 4.07
A6: UST2Y (BEARISH)
A7: 2-Year U.S. Treasury Yield | B7: 3.62 | C7: 3.49 | D7: 3.52
A8: HYG (NEUTRAL)
A9: High Yield | B9: 79.85 | C9: 80.61 | D9: 80.37
A10: LQD (BULLISH)
A11: Investment Grade Corporate Bond ETF | B11: 110.1 | C11: 111.6 | D11: 110.9
A12: SPX (BULLISH)
A13: S&P 500 | B13: 6476 | C13: 6713 | D13: 6602
A14: COMPQ (BEARISH)
A15: NASDAQ Composite | B15: 21830 | C15: 22906 | D15: 22273
A16: RUT (BEARISH)
A17: Russell 2000 | B17: 2278 | C17: 2412 | D17: 2369
A18: XLK (BEARISH)
A19: Technology Select Sector SPDR Fund | B19: 267 | C19: 286 | D19: 273
A20: XLV (BULLISH)
A21: Health Care Select Sector SPDR Fund | B21: 151 | C21: 156 | D21: 154.61
A22: SSEC (BEARISH)
A23: Shanghai Composite | B23: 3806 | C23: 3961 | D23: 3836
A24: NIKK (NEUTRAL)
A25: Nikkei 225 Index | B25: 48218 | C25: 51210 | D25: 48625
A26: DAX (BEARISH)
A27: German DAX Composite | B27: 22708 | C27: 23815 | D27: 23091
A28: VIX (BULLISH)
A29: Volatility Index | B29: 19.87 | C29: 27.97 | D29: 23.43
A30: USD (BULLISH)
A31: U.S. Dollar Index | B31: 99.46 | C31: 100.57 | D31: 100.07
A32: EUR/USD (BEARISH)
A33: Euro to U.S. Dollar | B33: 1.148 | C33: 1.16 | D33: 1.154
A34: USD/YEN (BULLISH)
A35: U.S. Dollar to Japanese Yen | B35: 154.18 | C35: 157.97 | D35: 156.82
A36: GBP/USD (BEARISH)
A37: British Pound to U.S. Dollar | B37: 1.303 | C37: 1.319 | D37: 1.311
A38: CAD/USD (BEARISH)
A39: Canadian Dollar to U.S. Dollar | B39: 0.706 | C39: 0.717 | D39: 0.708
A40: WTIC (BEARISH)
...

Sheet Nov. 25.2025
A1: INDEX | B1: BUY TRADE | C1: SELL TRADE | D1: PREV. CLOSE
A2: UST30Y (BEARISH) | B2: 4.74 | C2: 4.64 | D2: 4.67
A3: 30-Year U.S. Treasury Yield
A4: UST10Y (BEARISH) | B4: 4.14 | C4: 4.01 | D4: 4.03
A5: 10-Year U.S. Treasury Yield
A6: UST2Y (BEARISH) | B6: 3.61 | C6: 3.47 | D6: 3.5
A7: 2-Year U.S. Treasury Yield
A8: HYG (BULLISH) | B8: 79.93 | C8: 80.69 | D8: 80.59
A9: High Yield
A10: LQD (BULLISH) | B10: 110.2 | C10: 111.7 | D10: 111.4
A11: Investment Grade Corporate Bond ETF
A12: SPX (BULLISH) | B12: 6496 | C12: 6762 | D12: 6705
A13: S&P 500
A14: COMPQ (NEUTRAL) | B14: 21912 | C14: 23204 | D14: 22872
A15: NASDAQ Composite
A16: RUT (BEARISH) | B16: 2296 | C16: 2446 | D16: 2414
A17: Russell 2000
A18: XLK (BEARISH) | B18: 268 | C18: 286 | D18: 280
A19: Technology Select Sector SPDR Fund
A20: XLV (BULLISH) | B20: 151 | C20: 157 | D20: 155.26
A21: Health Care Select Sector SPDR Fund
A22: SSEC (BEARISH) | B22: 3804 | C22: 3943 | D22: 3870
A23: Shanghai Composite
A24: NIKK (NEUTRAL) | B24: 47813 | C24: 49993 | D24: 48659
A25: Nikkei 225 Index
A26: DAX (BEARISH) | B26: 22567 | C26: 23765 | D26: 23239
A27: German DAX Composite
A28: VIX (BULLISH) | B28: 18.44 | C28: 27.44 | D28: 20.52
A29: Volatility Index
A30: USD (BULLISH) | B30: 99.53 | C30: 100.66 | D30: 100.12
A31: U.S. Dollar Index
A32: EUR/USD (BEARISH) | B32: 1.147 | C32: 1.16 | D32: 1.153
A33: Euro to U.S. Dollar
A34: USD/YEN (BULLISH) | B34: 154.34 | C34: 157.99 | D34: 156.38
A35: U.S. Dollar to Japanese Yen
A36: GBP/USD (BEARISH) | B36: 1.302 | C36: 1.319 | D36: 1.312
A37: British Pound to U.S. Dollar
A38: CAD/USD (BEARISH) | B38: 0.705 | C38: 0.717 | D38: 0.708
A39: Canadian Dollar to U.S. Dollar
A40: WTIC (BEARISH) | B40: 57.12 | C40: 60.73 | D40: 58.89
...

Sheet Nov. 26.2025
A1: INDEX | B1: BUY TRADE | C1: SELL TRADE | D1: PREV. CLOSE
A2: UST30Y (BEARISH) | B2: 4.73 | C2: 4.62 | D2: 4.65
A3: 30-Year U.S. Treasury Yield
A4: UST10Y (BEARISH) | B4: 4.11 | C4: 3.97 | D4: 4
A5: 10-Year U.S. Treasury Yield
A6: UST2Y (BEARISH) | B6: 3.57 | C6: 3.43 | D6: 3.46
A7: 2-Year U.S. Treasury Yield
A8: HYG (BULLISH) | B8: 80.1 | C8: 80.98 | D8: 80.87
A9: High Yield
A10: LQD (BULLISH) | B10: 110.3 | C10: 111.9 | D10: 111.7
A11: Investment Grade Corporate Bond ETF
A12: SPX (BULLISH) | B12: 6508 | C12: 6804 | D12: 6765
A13: S&P 500
A14: COMPQ (BULLISH) | B14: 22009 | C14: 23262 | D14: 23025
A15: NASDAQ Composite
A16: RUT (BULLISH) | B16: 2297 | C16: 2487 | D16: 2465
A17: Russell 2000
A18: XLK (BEARISH) | B18: 269 | C18: 287 | D18: 280
A19: Technology Select Sector SPDR Fund
A20: XLV (BULLISH) | B20: 153 | C20: 161 | D20: 158.77
A21: Health Care Select Sector SPDR Fund
A22: SSEC (BEARISH) | B22: 3791 | C22: 3933 | D22: 3864
A23: Shanghai Composite
A24: NIKK (BULLISH) | B24: 47803 | C24: 51301 | D24: 49559
A25: Nikkei 225 Index
A26: DAX (BEARISH) | B26: 22601 | C26: 23845 | D26: 23464
A27: German DAX Composite
A28: VIX (BULLISH) | B28: 17.28 | C28: 27.18 | D28: 18.56
A29: Volatility Index
A30: USD (BULLISH) | B30: 99.32 | C30: 100.58 | D30: 99.8
A31: U.S. Dollar Index
A32: EUR/USD (BEARISH) | B32: 1.148 | C32: 1.161 | D32: 1.158
A33: Euro to U.S. Dollar
A34: USD/YEN (BULLISH) | B34: 154.65 | C34: 157.98 | D34: 156.51
A35: U.S. Dollar to Japanese Yen
A36: GBP/USD (BEARISH) | B36: 1.303 | C36: 1.322 | D36: 1.317
A37: British Pound to U.S. Dollar
A38: CAD/USD (BEARISH) | B38: 0.705 | C38: 0.717 | D38: 0.709
A39: Canadian Dollar to U.S. Dollar
A40: WTIC (BEARISH) | B40: 57.03 | C40: 59.73 | D40: 58.11
...

Sheet Nov 28.2025
A1: INDEX | B1: BUY TRADE | C1: SELL TRADE | D1: PREV. CLOSE
A2: UST30Y (BEARISH) | B2: 4.72 | C2: 4.6 | D2: 4.64
A3: 30-Year U.S. Treasury Yield
A4: UST10Y (BEARISH) | B4: 4.09 | C4: 3.95 | D4: 4
A5: 10-Year U.S. Treasury Yield
A6: UST2Y (BEARISH) | B6: 3.55 | C6: 3.43 | D6: 3.48
A7: 2-Year U.S. Treasury Yield
A8: HYG (BULLISH) | B8: 80.31 | C8: 81.1 | D8: 80.95
A9: High Yield
A10: LQD (BULLISH) | B10: 110.6 | C10: 112.4 | D10: 112.1
A11: Investment Grade Corporate Bond ETF
A12: SPX (BULLISH) | B12: 6503 | C12: 6851 | D12: 6812
A13: S&P 500
A14: COMPQ (BULLISH) | B14: 21967 | C14: 23498 | D14: 23214
A15: NASDAQ Composite
A16: RUT (BULLISH) | B16: 2307 | C16: 2506 | D16: 2486
A17: Russell 2000
A18: XLK (NEUTRAL) | B18: 269 | C18: 288 | D18: 284
A19: Technology Select Sector SPDR Fund
A20: XLV (BULLISH) | B20: 154 | C20: 161 | D20: 158.42
A21: Health Care Select Sector SPDR Fund
A22: SSEC (BEARISH) | B22: 3799 | C22: 3973 | D22: 3888
A23: Shanghai Composite
A24: NIKK (BULLISH) | B24: 47882 | C24: 51006 | D24: 50253
A25: Nikkei 225 Index
A26: DAX (BEARISH) | B26: 22807 | C26: 23890 | D26: 23767
A27: German DAX Composite
A28: VIX (BULLISH) | B28: 16.04 | C28: 27.76 | D28: 17.19
A29: Volatility Index
A30: USD (BULLISH) | B30: 99.4 | C30: 100.51 | D30: 99.69
A31: U.S. Dollar Index
A32: EUR/USD (BEARISH) | B32: 1.148 | C32: 1.161 | D32: 1.157
A33: Euro to U.S. Dollar
A34: USD/YEN (BULLISH) | B34: 155.09 | C34: 157.91 | D34: 156.16
A35: U.S. Dollar to Japanese Yen
A36: GBP/USD (BEARISH) | B36: 1.302 | C36: 1.324 | D36: 1.321
A37: British Pound to U.S. Dollar
A38: CAD/USD (BEARISH) | B38: 0.706 | C38: 0.716 | D38: 0.712
A39: Canadian Dollar to U.S. Dollar
A40: WTIC (BEARISH) | B40: 57.14 | C40: 59.95 | D40: 58.65
...

Sheet Dec 1.2025
A1: INDEX | B1: BUY TRADE | C1: SELL TRADE | D1: PREV. CLOSE
A2: UST30Y (BEARISH) | B2: 4.74 | C2: 4.6 | D2: 4.67
A3: 30-Year U.S. Treasury Yield
A4: UST10Y (BEARISH) | B4: 4.13 | C4: 3.95 | D4: 4.02
A5: 10-Year U.S. Treasury Yield
A6: UST2Y (BEARISH) | B6: 3.6 | C6: 3.43 | D6: 3.5
A7: 2-Year U.S. Treasury Yield
A8: HYG (BULLISH) | B8: 80.45 | C8: 81.22 | D8: 80.99
A9: High Yield
A10: LQD (BULLISH) | B10: 110.3 | C10: 112.5 | D10: 111.9
A11: Investment Grade Corporate Bond ETF
A12: SPX (BULLISH) | B12: 6538 | C12: 6876 | D12: 6849
A13: S&P 500
A14: COMPQ (BULLISH) | B14: 21924 | C14: 23540 | D14: 23365
A15: NASDAQ Composite
A16: RUT (BULLISH) | B16: 2310 | C16: 2518 | D16: 2500
A17: Russell 2000
A18: XLK (BULLISH) | B18: 271 | C18: 290 | D18: 286
A19: Technology Select Sector SPDR Fund
A20: XLV (BULLISH) | B20: 153 | C20: 161 | D20: 157.65
A21: Health Care Select Sector SPDR Fund
A22: SSEC (NEUTRAL) | B22: 3821 | C22: 3965 | D22: 3914
A23: Shanghai Composite
A24: NIKK (NEUTRAL) | B24: 47950 | C24: 50849 | D24: 49303
A25: Nikkei 225 Index
A26: DAX (BEARISH) | B26: 22859 | C26: 23849 | D26: 23836
A27: German DAX Composite
A28: VIX (BEARISH) | B28: 15.29 | C28: 26.42 | D28: 16.35
A29: Volatility Index
A30: USD (BULLISH) | B30: 99.02 | C30: 100.5 | D30: 99.13
A31: U.S. Dollar Index
A32: EUR/USD (BEARISH) | B32: 1.149 | C32: 1.164 | D32: 1.164
A33: Euro to U.S. Dollar
A34: USD/YEN (BULLISH) | B34: 154.67 | C34: 157.63 | D34: 154.96
A35: U.S. Dollar to Japanese Yen
A36: GBP/USD (BEARISH) | B36: 1.304 | C36: 1.329 | D36: 1.325
A37: British Pound to U.S. Dollar
A38: CAD/USD (BEARISH) | B38: 0.707 | C38: 0.716 | D38: 0.716
A39: Canadian Dollar to U.S. Dollar
A40: WTIC (BEARISH) | B40: 57.96 | C40: 60.74 | D40: 59.44
...

Sheet Dec 2. 2025
A1: INDEX | B1: BUY TRADE | C1: SELL TRADE | D1: PREV. CLOSE
A2: UST30Y (BEARISH) | B2: 4.79 | C2: 4.61 | D2: 4.74
A3: 30-Year U.S. Treasury Yield
A4: UST10Y (BEARISH) | B4: 4.13 | C4: 3.95 | D4: 4.09
A5: 10-Year U.S. Treasury Yield
A6: UST2Y (BEARISH) | B6: 3.6 | C6: 3.43 | D6: 3.55
A7: 2-Year U.S. Treasury Yield
A8: HYG (BULLISH) | B8: 80.45 | C8: 81.22 | D8: 80.47
A9: High Yield
A10: LQD (BULLISH) | B10: 110.3 | C10: 112 | D10: 110.9
A11: Investment Grade Corporate Bond ETF
A12: SPX (BULLISH) | B12: 6609 | C12: 6850 | D12: 6812
A13: S&P 500
A14: COMPQ (BULLISH) | B14: 22317 | C14: 23566 | D14: 23275
A15: NASDAQ Composite
A16: RUT (BULLISH) | B16: 2313 | C16: 2509 | D16: 2469
A17: Russell 2000
A18: XLK (BULLISH) | B18: 271 | C18: 291 | D18: 286
A19: Technology Select Sector SPDR Fund
A20: XLV (BULLISH) | B20: 152 | C20: 161 | D20: 155.29
A21: Health Care Select Sector SPDR Fund
A22: SSEC (BEARISH) | B22: 3801 | C22: 3924 | D22: 3897
A23: Shanghai Composite
A24: NIKK (BULLISH) | B24: 47892 | C24: 50583 | D24: 49303
A25: Nikkei 225 Index
A26: DAX (BEARISH) | B26: 22912 | C26: 23844 | D26: 23589
A27: German DAX Composite
A28: BSE (BULLISH) | B28: 84506 | C28: 86333 | D28: 85138
A29: BSE SENSEX
A30: VIX (BEARISH) | B30: 15.79 | C30: 26.43 | D30: 17.24
A31: Volatility Index
A32: USD (BULLISH) | B32: 99.16 | C32: 100.39 | D32: 99.45
A33: U.S. Dollar Index
A34: EUR/USD (NEUTRAL) | B34: 1.151 | C34: 1.163 | D34: 1.161
A35: Euro to U.S. Dollar
A36: USD/YEN (BULLISH) | B36: 155.03 | C36: 157.64 | D36: 155.98
A37: U.S. Dollar to Japanese Yen
A38: GBP/USD (BEARISH) | B38: 1.304 | C38: 1.33 | D38: 1.321
A39: British Pound to U.S. Dollar
A40: CAD/USD (BEARISH) | B40: 0.706 | C40: 0.716 | D40: 0.713
...

Sheet Dec 3. 2025
A1: INDEX | B1: BUY TRADE | C1: SELL TRADE | D1: PREV. CLOSE
A2: UST30Y (BEARISH) | B2: 4.78 | C2: 4.63 | D2: 4.75
A3: 30-Year U.S. Treasury Yield
A4: UST10Y (BEARISH) | B4: 4.12 | C4: 3.96 | D4: 4.09
A5: 10-Year U.S. Treasury Yield
A6: UST2Y (BEARISH) | B6: 3.58 | C6: 3.43 | D6: 3.52
A7: 2-Year U.S. Treasury Yield
A8: HYG (BULLISH) | B8: 80.12 | C8: 81.06 | D8: 80.62
A9: High Yield
A10: LQD (BULLISH) | B10: 110.2 | C10: 112.1 | D10: 110.9
A11: Investment Grade Corporate Bond ETF
A12: SPX (BULLISH) | B12: 6614 | C12: 6909 | D12: 6829
A13: S&P 500
A14: COMPQ (BULLISH) | B14: 23396 | C14: 23841 | D14: 23413
A15: NASDAQ Composite
A16: RUT (BULLISH) | B16: 2382 | C16: 2523 | D16: 2464
A17: Russell 2000
A18: XLK (BULLISH) | B18: 274 | C18: 295 | D18: 289
A19: Technology Select Sector SPDR Fund
A20: XLV (BULLISH) | B20: 151 | C20: 161 | D20: 154.36
A21: Health Care Select Sector SPDR Fund
A22: SSEC (BEARISH) | B22: 3807 | C22: 3917 | D22: 3878
A23: Shanghai Composite
A24: NIKK (BULLISH) | B24: 48501 | C24: 50601 | D24: 49864
A25: Nikkei 225 Index
A26: DAX (BEARISH) | B26: 23001 | C26: 24016 | D26: 23710
A27: German DAX Composite
A28: BSE (BULLISH) | B28: 84516 | C28: 86339 | D28: 85106
A29: BSE SENSEX
A30: VIX (BEARISH) | B30: 14.61 | C30: 25.31 | D30: 16.59
A31: Volatility Index
A32: USD (NEUTRAL) | B32: 98.79 | C32: 100.35 | D32: 98.96
A33: U.S. Dollar Index
A34: EUR/USD (NEUTRAL) | B34: 1.151 | C34: 1.167 | D34: 1.167
A35: Euro to U.S. Dollar
A36: USD/YEN (BULLISH) | B36: 154.81 | C36: 157 | D36: 155.41
A37: U.S. Dollar to Japanese Yen
A38: GBP/USD (BEARISH) | B38: 1.306 | C38: 1.33 | D38: 1.33
A39: British Pound to U.S. Dollar
A40: CAD/USD (BEARISH) | B40: 0.709 | C40: 0.719 | D40: 0.717
...

Sheet Dec 4.2025
A1: INDEX | B1: BUY TRADE | C1: SELL TRADE | D1: PREV. CLOSE
A2: UST30Y (BEARISH) | B2: 4.77 | C2: 4.64 | D2: 4.73
A3: 30-Year U.S. Treasury Yield
A4: UST10Y (BEARISH) | B4: 4.12 | C4: 3.96 | D4: 4.07
A5: 10-Year U.S. Treasury Yield
A6: UST2Y (BEARISH) | B6: 3.57 | C6: 3.43 | D6: 3.5
A7: 2-Year U.S. Treasury Yield
A8: HYG (BULLISH) | B8: 80.16 | C8: 81.11 | D8: 80.69
A9: High Yield
A10: LQD (BULLISH) | B10: 110.2 | C10: 112 | D10: 111.2
A11: Investment Grade Corporate Bond ETF
A12: SPX (BULLISH) | B12: 6629 | C12: 6945 | D12: 6849
A13: S&P 500
A14: COMPQ (BULLISH) | B14: 23411 | C14: 23986 | D14: 23454
A15: NASDAQ Composite
A16: RUT (BULLISH) | B16: 2417 | C16: 2559 | D16: 2512
A17: Russell 2000
A18: XLK (BULLISH) | B18: 278 | C18: 296 | D18: 290
A19: Technology Select Sector SPDR Fund
A20: XLV (BULLISH) | B20: 151 | C20: 160 | D20: 155.08
A21: Health Care Select Sector SPDR Fund
A22: SSEC (BEARISH) | B22: 3814 | C22: 3915 | D22: 3875
A23: Shanghai Composite
A24: NIKK (BULLISH) | B24: 48409 | C24: 51300 | D24: 51028
A25: Nikkei 225 Index
A26: DAX (BEARISH) | B26: 23018 | C26: 24069 | D26: 23693
A27: German DAX Composite
A28: VIX (BEARISH) | B28: 14.41 | C28: 24.98 | D28: 16.08
A29: Volatility Index
A30: USD (NEUTRAL) | B30: 98.57 | C30: 100.22 | D30: 98.83
A31: U.S. Dollar Index
A32: EUR/USD (BULLISH) | B32: 1.153 | C32: 1.171 | D32: 1.167
A33: Euro to U.S. Dollar
A34: USD/YEN (BULLISH) | B34: 154.45 | C34: 157.01 | D34: 154.66
A35: U.S. Dollar to Japanese Yen
A36: GBP/USD (NEUTRAL) | B36: 1.31 | C36: 1.339 | D36: 1.335
A37: British Pound to U.S. Dollar
A38: CAD/USD (NEUTRAL) | B38: 0.709 | C38: 0.72 | D38: 0.715
A39: Canadian Dollar to U.S. Dollar
A40: WTIC (BEARISH) | B40: 57.92 | C40: 59.85 | D40: 59.11
...

Sheet Dec 5.2025
A1: INDEX | B1: BUY TRADE | C1: SELL TRADE | D1: PREV. CLOSE
A2: UST30Y (BEARISH) | B2: 4.77 | C2: 4.65 | D2: 4.76
A3: 30-Year U.S. Treasury Yield
A4: UST10Y (BEARISH) | B4: 4.13 | C4: 3.96 | D4: 4.1
A5: 10-Year U.S. Treasury Yield
A6: UST2Y (BEARISH) | B6: 3.56 | C6: 3.44 | D6: 3.53
A7: 2-Year U.S. Treasury Yield
A8: HYG (BULLISH) | B8: 80.22 | C8: 81.01 | D8: 80.75
A9: High Yield
A10: LQD (BULLISH) | B10: 110.3 | C10: 111.9 | D10: 111
A11: Investment Grade Corporate Bond ETF
A12: SPX (BULLISH) | B12: 6720 | C12: 6956 | D12: 6857
A13: S&P 500
A14: COMPQ (BULLISH) | B14: 22488 | C14: 23960 | D14: 23505
A15: NASDAQ Composite
A16: RUT (BULLISH) | B16: 2444 | C16: 2565 | D16: 2531
A17: Russell 2000
A18: XLK (BULLISH) | B18: 139 | C18: 149 | D18: 146
A19: Technology Select Sector SPDR Fund
A20: XLV (BULLISH) | B20: 151 | C20: 160 | D20: 153.9
A21: Health Care Select Sector SPDR Fund
A22: SSEC (NEUTRAL) | B22: 3827 | C22: 3920 | D22: 3902
A23: Shanghai Composite
A24: NIKK (BULLISH) | B24: 48512 | C24: 51209 | D24: 50491
A25: Nikkei 225 Index
A26: DAX (NEUTRAL) | B26: 23209 | C26: 24054 | D26: 23882
A27: German DAX Composite
A28: VIX (BEARISH) | B28: 14.22 | C28: 21.72 | D28: 15.78
A29: Volatility Index
A30: USD (BEARISH) | B30: 98.68 | C30: 99.78 | D30: 99.01
A31: U.S. Dollar Index
A32: EUR/USD (BULLISH) | B32: 1.154 | C32: 1.17 | D32: 1.165
A33: Euro to U.S. Dollar
A34: USD/YEN (BULLISH) | B34: 154.56 | C34: 156.84 | D34: 155.2
A35: U.S. Dollar to Japanese Yen
A36: GBP/USD (NEUTRAL) | B36: 1.312 | C36: 1.339 | D36: 1.334
A37: British Pound to U.S. Dollar
A38: CAD/USD (NEUTRAL) | B38: 0.71 | C38: 0.72 | D38: 0.717
A39: Canadian Dollar to U.S. Dollar
A40: WTIC (BEARISH) | B40: 57.86 | C40: 59.99 | D40: 59.7
...

Sheet Dec 8.2025
A1: INDEX | B1: BUY TRADE | C1: SELL TRADE | D1: PREV. CLOSE
A2: UST30Y (BULLISH) | B2: 4.82 | C2: 4.67 | D2: 4.79
A3: 30-Year U.S. Treasury Yield
A4: UST10Y (BEARISH) | B4: 4.17 | C4: 3.96 | D4: 4.14
A5: 10-Year U.S. Treasury Yield
A6: UST2Y (BEARISH) | B6: 3.6 | C6: 3.46 | D6: 3.57
A7: 2-Year U.S. Treasury Yield
A8: HYG (BULLISH) | B8: 80.23 | C8: 80.99 | D8: 80.75
A9: High Yield
A10: LQD (BULLISH) | B10: 110.3 | C10: 111.7 | D10: 110.9
A11: Investment Grade Corporate Bond ETF
A12: SPX (BULLISH) | B12: 6714 | C12: 6926 | D12: 6870
A13: S&P 500
A14: COMPQ (BULLISH) | B14: 22905 | C14: 23936 | D14: 23578
A15: NASDAQ Composite
A16: RUT (BULLISH) | B16: 2450 | C16: 2563 | D16: 2521
A17: Russell 2000
A18: XLK (BULLISH) | B18: 139 | C18: 149 | D18: 147
A19: Technology Select Sector SPDR Fund
A20: XLV (BULLISH) | B20: 151 | C20: 160 | D20: 153.26
A21: Health Care Select Sector SPDR Fund
A22: SSEC (NEUTRAL) | B22: 3838 | C22: 3936 | D22: 3924
A23: Shanghai Composite
A24: NIKK (BULLISH) | B24: 48907 | C24: 51308 | D24: 50581
A25: Nikkei 225 Index
A26: DAX (NEUTRAL) | B26: 23331 | C26: 24153 | D26: 24028
A27: German DAX Composite
A28: VIX (BEARISH) | B28: 14.18 | C28: 20.19 | D28: 15.41
A29: Volatility Index
A30: USD (BEARISH) | B30: 98.58 | C30: 99.7 | D30: 98.99
A31: U.S. Dollar Index
A32: EUR/USD (BULLISH) | B32: 1.158 | C32: 1.17 | D32: 1.165
A33: Euro to U.S. Dollar
A34: USD/YEN (BULLISH) | B34: 154.62 | C34: 156.8 | D34: 155.63
A35: U.S. Dollar to Japanese Yen
A36: GBP/USD (BULLISH) | B36: 1.315 | C36: 1.339 | D36: 1.332
A37: British Pound to U.S. Dollar
A38: CAD/USD (BULLISH) | B38: 0.713 | C38: 0.725 | D38: 0.724
A39: Canadian Dollar to U.S. Dollar
A40: WTIC (BEARISH) | B40: 57.96 | C40: 60.34 | D40: 60.14
...

Sheet Dec. 9.2025
A1: INDEX | B1: BUY TRADE | C1: SELL TRADE | D1: PREV. CLOSE
A2: UST30Y (BULLISH) | B2: 4.85 | C2: 4.71 | D2: 4.8
A3: 30-Year U.S. Treasury Yield
A4: UST10Y (BEARISH) | B4: 4.18 | C4: 3.95 | D4: 4.17
A5: 10-Year U.S. Treasury Yield
A6: UST2Y (BEARISH) | B6: 3.6 | C6: 3.45 | D6: 3.58
A7: 2-Year U.S. Treasury Yield
A8: HYG (BULLISH) | B8: 80.27 | C8: 80.91 | D8: 80.55
A9: High Yield
A10: LQD (BULLISH) | B10: 110.3 | C10: 111.8 | D10: 110.6
A11: Investment Grade Corporate Bond ETF
A12: SPX (BULLISH) | B12: 6762 | C12: 6902 | D12: 6846
A13: S&P 500
A14: COMPQ (BULLISH) | B14: 23140 | C14: 23810 | D14: 23545
A15: NASDAQ Composite
A16: RUT (BULLISH) | B16: 2444 | C16: 2532 | D16: 2520
A17: Russell 2000
A18: XLK (BULLISH) | B18: 141 | C18: 152 | D18: 148
A19: Technology Select Sector SPDR Fund
A20: XLV (BULLISH) | B20: 150 | C20: 161 | D20: 151.43
A21: Health Care Select Sector SPDR Fund
A22: SSEC (NEUTRAL) | B22: 3840 | C22: 3930 | D22: 3909
A23: Shanghai Composite
A24: NIKK (BULLISH) | B24: 48951 | C24: 51202 | D24: 50655
A25: Nikkei 225 Index
A26: DAX (NEUTRAL) | B26: 23498 | C26: 24199 | D26: 24046
A27: German DAX Composite
A28: VIX (BEARISH) | B28: 14.71 | C28: 18.92 | D28: 16.66
A29: Volatility Index
A30: USD (BEARISH) | B30: 98.6 | C30: 99.74 | D30: 99.12
A31: U.S. Dollar Index
A32: EUR/USD (BULLISH) | B32: 1.159 | C32: 1.169 | D32: 1.164
A33: Euro to U.S. Dollar
A34: USD/YEN (BULLISH) | B34: 154.72 | C34: 156.71 | D34: 156.28
A35: U.S. Dollar to Japanese Yen
A36: GBP/USD (BULLISH) | B36: 1.32 | C36: 1.34 | D36: 1.332
A37: British Pound to U.S. Dollar
A38: CAD/USD (BULLISH) | B38: 0.715 | C38: 0.726 | D38: 0.722
A39: Canadian Dollar to U.S. Dollar
A40: WTIC (BEARISH) | B40: 57.7 | C40: 60.27 | D40: 58.85
...

Sheet Dec 10.2025
A1: INDEX | B1: BUY TRADE | C1: SELL TRADE | D1: PREV. CLOSE
A2: UST30Y (BULLISH) | B2: 4.86 | C2: 4.72 | D2: 4.81
A3: 30-Year U.S. Treasury Yield
A4: UST10Y (BEARISH) | B4: 4.22 | C4: 3.99 | D4: 4.19
A5: 10-Year U.S. Treasury Yield
A6: UST2Y (BEARISH) | B6: 3.65 | C6: 3.45 | D6: 3.62
A7: 2-Year U.S. Treasury Yield
A8: HYG (BULLISH) | B8: 80.29 | C8: 80.91 | D8: 80.46
A9: High Yield
A10: LQD (BULLISH) | B10: 110 | C10: 111.6 | D10: 110.5
A11: Investment Grade Corporate Bond ETF
A12: SPX (BULLISH) | B12: 6787 | C12: 6897 | D12: 6840
A13: S&P 500
A14: COMPQ (BULLISH) | B14: 23103 | C14: 23883 | D14: 23576
A15: NASDAQ Composite
A16: RUT (BULLISH) | B16: 2470 | C16: 2559 | D16: 2526
A17: Russell 2000
A18: XLK (BULLISH) | B18: 143 | C18: 152 | D18: 148
A19: Technology Select Sector SPDR Fund
A20: XLV (BULLISH) | B20: 149 | C20: 160 | D20: 150
A21: Health Care Select Sector SPDR Fund
A22: SSEC (BEARISH) | B22: 3842 | C22: 3925 | D22: 3900
A23: Shanghai Composite
A24: NIKK (BULLISH) | B24: 49068 | C24: 51328 | D24: 50602
A25: Nikkei 225 Index
A26: DAX (NEUTRAL) | B26: 23422 | C26: 24204 | D26: 24162
A27: German DAX Composite
A28: VIX (BEARISH) | B28: 15.19 | C28: 18.23 | D28: 16.93
A29: Volatility Index
A30: USD (BEARISH) | B30: 98.68 | C30: 99.61 | D30: 99.11
A31: U.S. Dollar Index
A32: EUR/USD (BULLISH) | B32: 1.159 | C32: 1.171 | D32: 1.164
A33: Euro to U.S. Dollar
A34: USD/YEN (BULLISH) | B34: 154.81 | C34: 157.13 | D34: 156.71
A35: U.S. Dollar to Japanese Yen
A36: GBP/USD (BULLISH) | B36: 1.322 | C36: 1.341 | D36: 1.331
A37: British Pound to U.S. Dollar
A38: CAD/USD (BULLISH) | B38: 0.715 | C38: 0.726 | D38: 0.722
A39: Canadian Dollar to U.S. Dollar
A40: WTIC (BEARISH) | B40: 57.95 | C40: 60.08 | D40: 58.39
...

Sheet Dec. 11.2025
A1: INDEX | B1: BUY TRADE | C1: SELL TRADE | D1: PREV. CLOSE
A2: UST30Y (BULLISH) | B2: 4.82 | C2: 4.69 | D2: 4.78
A3: 30-Year U.S. Treasury Yield
A4: UST10Y (BEARISH) | B4: 4.19 | C4: 3.99 | D4: 4.16
A5: 10-Year U.S. Treasury Yield
A6: UST2Y (BEARISH) | B6: 3.61 | C6: 3.46 | D6: 3.55
A7: 2-Year U.S. Treasury Yield
A8: HYG (BULLISH) | B8: 80.31 | C8: 80.94 | D8: 80.73
A9: High Yield
A10: LQD (BULLISH) | B10: 110.2 | C10: 111.6 | D10: 111
A11: Investment Grade Corporate Bond ETF
A12: SPX (BULLISH) | B12: 6801 | C12: 6918 | D12: 6886
A13: S&P 500
A14: COMPQ (BULLISH) | B14: 23206 | C14: 23881 | D14: 23654
A15: NASDAQ Composite
A16: RUT (BULLISH) | B16: 2481 | C16: 2582 | D16: 2559
A17: Russell 2000
A18: XLK (BULLISH) | B18: 142 | C18: 150 | D18: 149
A19: Technology Select Sector SPDR Fund
A20: XLV (BULLISH) | B20: 149 | C20: 157 | D20: 152
A21: Health Care Select Sector SPDR Fund
A22: XLY (BULLISH) | B22: 117 | C22: 121 | D22: 120
A23: Consumer Discretionary Select Sector SPDR Fund
A24: SSEC (BEARISH) | B24: 3843 | C24: 3923 | D24: 3873
A25: Shanghai Composite
A26: NIKK (BULLISH) | B26: 49036 | C26: 51316 | D26: 50148
A27: Nikkei 225 Index
A28: DAX (NEUTRAL) | B28: 23501 | C28: 24296 | D28: 24130
A29: German DAX Composite
A30: VIX (BEARISH) | B30: 14.72 | C30: 18.03 | D30: 15.77
A31: Volatility Index
A32: USD (BEARISH) | B32: 98.25 | C32: 99.26 | D32: 98.5
A33: U.S. Dollar Index
A34: EUR/USD (BULLISH) | B34: 1.161 | C34: 1.173 | D34: 1.171
A35: Euro to U.S. Dollar
A36: USD/YEN (BULLISH) | B36: 154.53 | C36: 156.81 | D36: 155.54
A37: U.S. Dollar to Japanese Yen
A38: GBP/USD (BULLISH) | B38: 1.324 | C38: 1.344 | D38: 1.339
A39: British Pound to U.S. Dollar
A40: CAD/USD (BULLISH) | B40: 0.716 | C40: 0.729 | D40: 0.724
...

Sheet Dec 12.2025
A1: INDEX | B1: BUY TRADE | C1: SELL TRADE | D1: PREV. CLOSE
A2: UST30Y (BULLISH) | B2: 4.84 | C2: 4.71 | D2: 4.8
A3: 30-Year U.S. Treasury Yield
A4: UST10Y (BEARISH) | B4: 4.22 | C4: 4.02 | D4: 4.16
A5: 10-Year U.S. Treasury Yield
A6: UST2Y (BEARISH) | B6: 3.62 | C6: 3.46 | D6: 3.55
A7: 2-Year U.S. Treasury Yield
A8: HYG (BULLISH) | B8: 80.34 | C8: 80.96 | D8: 80.72
A9: High Yield
A10: LQD (BULLISH) | B10: 110.3 | C10: 111.4 | D10: 110.8
A11: Investment Grade Corporate Bond ETF
A12: SPX (BULLISH) | B12: 6812 | C12: 6937 | D12: 6901
A13: S&P 500
A14: COMPQ (BULLISH) | B14: 23291 | C14: 23827 | D14: 23593
A15: NASDAQ Composite
A16: RUT (BULLISH) | B16: 2482 | C16: 2610 | D16: 2590
A17: Russell 2000
A18: XLK (BULLISH) | B18: 143 | C18: 150 | D18: 148
A19: Technology Select Sector SPDR Fund
A20: XLV (BULLISH) | B20: 149 | C20: 157 | D20: 154
A21: Health Care Select Sector SPDR Fund
A22: XLY (BULLISH) | B22: 118 | C22: 122 | D22: 120
A23: Consumer Discretionary Select Sector SPDR Fund
A24: SSEC (BEARISH) | B24: 3844 | C24: 3923 | D24: 3889
A25: Shanghai Composite
A26: NIKK (BULLISH) | B26: 49039 | C26: 51616 | D26: 50836
A27: Nikkei 225 Index
A28: DAX (BULLISH) | B28: 23602 | C28: 24601 | D28: 24294
A29: German DAX Composite
A30: VIX (BEARISH) | B30: 14.49 | C30: 17.24 | D30: 14.85
A31: Volatility Index
A32: USD (BEARISH) | B32: 98.18 | C32: 99.18 | D32: 98.45
A33: U.S. Dollar Index
A34: EUR/USD (BULLISH) | B34: 1.162 | C34: 1.174 | D34: 1.173
A35: Euro to U.S. Dollar
A36: USD/YEN (BULLISH) | B36: 154.52 | C36: 156.8 | D36: 156
A37: U.S. Dollar to Japanese Yen
A38: GBP/USD (BULLISH) | B38: 1.324 | C38: 1.344 | D38: 1.338
A39: British Pound to U.S. Dollar
A40: CAD/USD (BULLISH) | B40: 0.716 | C40: 0.729 | D40: 0.726
...

Sheet Dec. 15.2025
A1: INDEX | B1: BUY TRADE | C1: SELL TRADE | D1: PREV. CLOSE
A2: UST30Y (BULLISH) | B2: 4.86 | C2: 4.73 | D2: 4.84
A3: 30-Year U.S. Treasury Yield
A4: UST10Y (BEARISH) | B4: 4.23 | C4: 4.05 | D4: 4.18
A5: 10-Year U.S. Treasury Yield
A6: UST2Y (BEARISH) | B6: 3.62 | C6: 3.46 | D6: 3.53
A7: 2-Year U.S. Treasury Yield
A8: HYG (BULLISH) | B8: 80.35 | C8: 80.94 | D8: 80.57
A9: High Yield
A10: LQD (BULLISH) | B10: 110 | C10: 111.5 | D10: 110.2
A11: Investment Grade Corporate Bond ETF
A12: SPX (BULLISH) | B12: 6805 | C12: 6913 | D12: 6827
A13: S&P 500
A14: COMPQ (BULLISH) | B14: 23195 | C14: 23799 | D14: 23195
A15: NASDAQ Composite
A16: RUT (BULLISH) | B16: 2497 | C16: 2592 | D16: 2551
A17: Russell 2000
A18: XLK (BULLISH) | B18: 141 | C18: 148 | D18: 144
A19: Technology Select Sector SPDR Fund
A20: XLV (BULLISH) | B20: 150 | C20: 157 | D20: 154
A21: Health Care Select Sector SPDR Fund
A22: XLY (BULLISH) | B22: 118 | C22: 122 | D22: 121
A23: Consumer Discretionary Select Sector SPDR Fund
A24: SSEC (BEARISH) | B24: 3843 | C24: 3923 | D24: 3867
A25: Shanghai Composite
A26: NIKK (BULLISH) | B26: 49312 | C26: 51408 | D26: 50168
A27: Nikkei 225 Index
A28: DAX (BULLISH) | B28: 23606 | C28: 24419 | D28: 24186
A29: German DAX Composite
A30: VIX (BEARISH) | B30: 14.53 | C30: 17.67 | D30: 15.74
A31: Volatility Index
A32: USD (BEARISH) | B32: 98.04 | C32: 99.02 | D32: 98.24
A33: U.S. Dollar Index
A34: EUR/USD (BULLISH) | B34: 1.163 | C34: 1.176 | D34: 1.175
A35: Euro to U.S. Dollar
A36: USD/YEN (NEUTRAL) | B36: 154.17 | C36: 156.65 | D36: 154.99
A37: U.S. Dollar to Japanese Yen
A38: GBP/USD (BULLISH) | B38: 1.327 | C38: 1.343 | D38: 1.339
A39: British Pound to U.S. Dollar
A40: CAD/USD (BULLISH) | B40: 0.717 | C40: 0.728 | D40: 0.726
...

Sheet Dec 16.2025
A1: INDEX | B1: BUY TRADE | C1: SELL TRADE | D1: PREV. CLOSE
A2: UST30Y (BULLISH) | B2: 4.88 | C2: 4.75 | D2: 4.85
A3: 30-Year U.S. Treasury Yield
A4: UST10Y (BEARISH) | B4: 4.23 | C4: 4.05 | D4: 4.18
A5: 10-Year U.S. Treasury Yield
A6: UST2Y (BEARISH) | B6: 3.6 | C6: 3.46 | D6: 3.52
A7: 2-Year U.S. Treasury Yield
A8: HYG (BULLISH) | B8: 80.39 | C8: 80.94 | D8: 80.61
A9: High Yield
A10: LQD (BULLISH) | B10: 110 | C10: 111.4 | D10: 110.3
A11: Investment Grade Corporate Bond ETF
A12: SPX (BULLISH) | B12: 6795 | C12: 6916 | D12: 6816
A13: S&P 500
A14: COMPQ (BULLISH) | B14: 22901 | C14: 23862 | D14: 23057
A15: NASDAQ Composite
A16: RUT (BULLISH) | B16: 2484 | C16: 2578 | D16: 2530
A17: Russell 2000
A18: XLK (BULLISH) | B18: 140 | C18: 148 | D18: 142
A19: Technology Select Sector SPDR Fund
A20: XLV (BULLISH) | B20: 152 | C20: 158 | D20: 156
A21: Health Care Select Sector SPDR Fund
A22: XLY (BULLISH) | B22: 119 | C22: 123 | D22: 122
A23: Consumer Discretionary Select Sector SPDR Fund
A24: SSEC (BEARISH) | B24: 3810 | C24: 3905 | D24: 3824
A25: Shanghai Composite
A26: NIKK (BULLISH) | B26: 49003 | C26: 51164 | D26: 49383
A27: Nikkei 225 Index
A28: DAX (BULLISH) | B28: 23708 | C28: 24436 | D28: 24229
A29: German DAX Composite
A30: VIX (BEARISH) | B30: 14.64 | C30: 17.83 | D30: 16.5
A31: Volatility Index
A32: USD (BEARISH) | B32: 97.84 | C32: 99.05 | D32: 98.14
A33: U.S. Dollar Index
A34: EUR/USD (BULLISH) | B34: 1.163 | C34: 1.181 | D34: 1.177
A35: Euro to U.S. Dollar
A36: USD/YEN (NEUTRAL) | B36: 154.07 | C36: 156.61 | D36: 154.8
A37: U.S. Dollar to Japanese Yen
A38: GBP/USD (BULLISH) | B38: 1.329 | C38: 1.345 | D38: 1.343
A39: British Pound to U.S. Dollar
A40: CAD/USD (BULLISH) | B40: 0.718 | C40: 0.728 | D40: 0.726
...

Sheet Dec 17.2025
A1: INDEX | B1: BUY TRADE | C1: SELL TRADE | D1: PREV. CLOSE
A2: UST30Y (BULLISH) | B2: 4.87 | C2: 4.74 | D2: 4.82
A3: 30-Year U.S. Treasury Yield
A4: UST10Y (BEARISH) | B4: 4.2 | C4: 4.07 | D4: 4.14
A5: 10-Year U.S. Treasury Yield
A6: UST2Y (BEARISH) | B6: 3.59 | C6: 3.46 | D6: 3.5
A7: 2-Year U.S. Treasury Yield
A8: HYG (BULLISH) | B8: 80.4 | C8: 80.91 | D8: 80.66
A9: High Yield
A10: LQD (BULLISH) | B10: 109.8 | C10: 111.1 | D10: 110.6
A11: Investment Grade Corporate Bond ETF
A12: SPX (BULLISH) | B12: 6777 | C12: 6921 | D12: 6800
A13: S&P 500
A14: COMPQ (BULLISH) | B14: 22954 | C14: 23893 | D14: 23111
A15: NASDAQ Composite
A16: RUT (BULLISH) | B16: 2484 | C16: 2578 | D16: 2519
A17: Russell 2000
A18: XLK (BULLISH) | B18: 140 | C18: 148 | D18: 143
A19: Technology Select Sector SPDR Fund
A20: XLV (BULLISH) | B20: 151 | C20: 157 | D20: 154
A21: Health Care Select Sector SPDR Fund
A22: XLY (BULLISH) | B22: 120 | C22: 124 | D22: 122
A23: Consumer Discretionary Select Sector SPDR Fund
A24: SSEC (BEARISH) | B24: 3820 | C24: 3898 | D24: 3870
A25: Shanghai Composite
A26: NIKK (BULLISH) | B26: 49303 | C26: 51111 | D26: 49512
A27: Nikkei 225 Index
A28: DAX (BULLISH) | B28: 23813 | C28: 24407 | D28: 24076
A29: German DAX Composite
A30: VIX (BEARISH) | B30: 14.64 | C30: 17.81 | D30: 16.48
A31: Volatility Index
A32: USD (BEARISH) | B32: 97.84 | C32: 99.03 | D32: 98.56
A33: U.S. Dollar Index
A34: EUR/USD (BULLISH) | B34: 1.164 | C34: 1.181 | D34: 1.172
A35: Euro to U.S. Dollar
A36: USD/YEN (BULLISH) | B36: 154.4 | C36: 156.78 | D36: 155.51
A37: U.S. Dollar to Japanese Yen
A38: GBP/USD (BULLISH) | B38: 1.327 | C38: 1.345 | D38: 1.333
A39: British Pound to U.S. Dollar
A40: CAD/USD (BULLISH) | B40: 0.72 | C40: 0.729 | D40: 0.725
...

Sheet Dec 18.2025
A1: INDEX | B1: BUY TRADE | C1: SELL TRADE | D1: PREV. CLOSE
A2: UST30Y (BULLISH) | B2: 4.88 | C2: 4.76 | D2: 4.84
A3: 30-Year U.S. Treasury Yield
A4: UST10Y (BEARISH) | B4: 4.21 | C4: 4.09 | D4: 4.16
A5: 10-Year U.S. Treasury Yield
A6: UST2Y (BEARISH) | B6: 3.58 | C6: 3.43 | D6: 3.49
A7: 2-Year U.S. Treasury Yield
A8: HYG (BULLISH) | B8: 80.41 | C8: 80.88 | D8: 80.56
A9: High Yield
A10: LQD (BULLISH) | B10: 109.9 | C10: 111.2 | D10: 110.4
A11: Investment Grade Corporate Bond ETF
A12: SPX (BULLISH) | B12: 6694 | C12: 6925 | D12: 6721
A13: S&P 500
A14: COMPQ (BULLISH) | B14: 22602 | C14: 23972 | D14: 22693
A15: NASDAQ Composite
A16: RUT (BULLISH) | B16: 2475 | C16: 2590 | D16: 2492
A17: Russell 2000
A18: XLK (NEUTRAL) | B18: 136 | C18: 145 | D18: 139
A19: Technology Select Sector SPDR Fund
A20: XLV (BULLISH) | B20: 149 | C20: 157 | D20: 154
A21: Health Care Select Sector SPDR Fund
A22: XLY (BULLISH) | B22: 119 | C22: 124 | D22: 121
A23: Consumer Discretionary Select Sector SPDR Fund
A24: SSEC (BEARISH) | B24: 3814 | C24: 3899 | D24: 3876
A25: Shanghai Composite
A26: NIKK (BULLISH) | B26: 48521 | C26: 51107 | D26: 49001
A27: Nikkei 225 Index
A28: DAX (BULLISH) | B28: 23818 | C28: 24301 | D28: 23960
A29: German DAX Composite
A30: VIX (BEARISH) | B30: 14.52 | C30: 18.01 | D30: 17.62
A31: Volatility Index
A32: USD (BEARISH) | B32: 97.78 | C32: 98.99 | D32: 98.52
A33: U.S. Dollar Index
A34: EUR/USD (BULLISH) | B34: 1.162 | C34: 1.181 | D34: 1.172
A35: Euro to U.S. Dollar
A36: USD/YEN (BULLISH) | B36: 154.57 | C36: 156.94 | D36: 155.77
A37: U.S. Dollar to Japanese Yen
A38: GBP/USD (BULLISH) | B38: 1.328 | C38: 1.345 | D38: 1.338
A39: British Pound to U.S. Dollar
A40: CAD/USD (BULLISH) | B40: 0.72 | C40: 0.729 | D40: 0.725
...

Sheet Dec 19.2025
A1: INDEX | B1: BUY TRADE | C1: SELL TRADE | D1: PREV. CLOSE
A2: UST30Y (BULLISH) | B2: 4.87 | C2: 4.76 | D2: 4.81
A3: 30-Year U.S. Treasury Yield
A4: UST10Y (BEARISH) | B4: 4.2 | C4: 4.1 | D4: 4.12
A5: 10-Year U.S. Treasury Yield
A6: UST2Y (BEARISH) | B6: 3.55 | C6: 3.43 | D6: 3.47
A7: 2-Year U.S. Treasury Yield
A8: HYG (BULLISH) | B8: 80.41 | C8: 80.89 | D8: 80.78
A9: High Yield
A10: LQD (BULLISH) | B10: 109.9 | C10: 111.3 | D10: 110.9
A11: Investment Grade Corporate Bond ETF
A12: SPX (BULLISH) | B12: 6712 | C12: 6937 | D12: 6774
A13: S&P 500
A14: COMPQ (BULLISH) | B14: 22632 | C14: 23913 | D14: 23006
A15: NASDAQ Composite
A16: RUT (BULLISH) | B16: 2484 | C16: 2600 | D16: 2507
A17: Russell 2000
A18: XLK (NEUTRAL) | B18: 137 | C18: 145 | D18: 142
A19: Technology Select Sector SPDR Fund
A20: XLV (BULLISH) | B20: 150 | C20: 157 | D20: 154
A21: Health Care Select Sector SPDR Fund
A22: XLY (BULLISH) | B22: 120 | C22: 125 | D22: 122
A23: Consumer Discretionary Select Sector SPDR Fund
A24: SSEC (BEARISH) | B24: 3820 | C24: 3922 | D24: 3890
A25: Shanghai Composite
A26: NIKK (BULLISH) | B26: 48898 | C26: 51319 | D26: 49507
A27: Nikkei 225 Index
A28: DAX (BULLISH) | B28: 23908 | C28: 24395 | D28: 24199
A29: German DAX Composite
A30: VIX (BEARISH) | B30: 14.73 | C30: 17.97 | D30: 16.87
A31: Volatility Index
A32: USD (BEARISH) | B32: 97.89 | C32: 99.04 | D32: 98.68
A33: U.S. Dollar Index
A34: EUR/USD (BULLISH) | B34: 1.163 | C34: 1.181 | D34: 1.171
A35: Euro to U.S. Dollar
A36: USD/YEN (BULLISH) | B36: 155.36 | C36: 157.49 | D36: 157.28
A37: U.S. Dollar to Japanese Yen
A38: GBP/USD (BULLISH) | B38: 1.329 | C38: 1.346 | D38: 1.337
A39: British Pound to U.S. Dollar
A40: CAD/USD (BULLISH) | B40: 0.721 | C40: 0.729 | D40: 0.724
...

Sheet Dec 22.2025
A1: INDEX | B1: BUY TRADE | C1: SELL TRADE | D1: PREV. CLOSE
A2: UST30Y (BULLISH) | B2: 4.88 | C2: 4.77 | D2: 4.82
A3: 30-Year U.S. Treasury Yield
A4: UST10Y (BEARISH) | B4: 4.21 | C4: 4.1 | D4: 4.14
A5: 10-Year U.S. Treasury Yield
A6: UST2Y (BEARISH) | B6: 3.53 | C6: 3.43 | D6: 3.49
A7: 2-Year U.S. Treasury Yield
A8: HYG (BULLISH) | B8: 80.1 | C8: 80.67 | D8: 80.36
A9: High Yield
A10: LQD (BULLISH) | B10: 109.8 | C10: 110.9 | D10: 110.1
A11: Investment Grade Corporate Bond ETF
A12: SPX (BULLISH) | B12: 6721 | C12: 6936 | D12: 6834
A13: S&P 500
A14: COMPQ (BULLISH) | B14: 22636 | C14: 23877 | D14: 23307
A15: NASDAQ Composite
A16: RUT (BULLISH) | B16: 2498 | C16: 2601 | D16: 2529
A17: Russell 2000
A18: XLK (BULLISH) | B18: 139 | C18: 148 | D18: 145
A19: Technology Select Sector SPDR Fund
A20: XLV (BULLISH) | B20: 151 | C20: 158 | D20: 155
A21: Health Care Select Sector SPDR Fund
A22: XLY (BULLISH) | B22: 121 | C22: 125 | D22: 122
A23: Consumer Discretionary Select Sector SPDR Fund
A24: SSEC (NEUTRAL) | B24: 3823 | C24: 3930 | D24: 3917
A25: Shanghai Composite
A26: NIKK (BULLISH) | B26: 49001 | C26: 51218 | D26: 50402
A27: Nikkei 225 Index
A28: DAX (BULLISH) | B28: 23912 | C28: 24398 | D28: 24288
A29: German DAX Composite
A30: VIX (BEARISH) | B30: 14.22 | C30: 17.29 | D30: 14.91
A31: Volatility Index
A32: USD (BEARISH) | B32: 98.01 | C32: 98.92 | D32: 98.45
A33: U.S. Dollar Index
A34: EUR/USD (BULLISH) | B34: 1.167 | C34: 1.18 | D34: 1.174
A35: Euro to U.S. Dollar
A36: USD/YEN (BULLISH) | B36: 155.54 | C36: 157.9 | D36: 157.41
A37: U.S. Dollar to Japanese Yen
A38: GBP/USD (BULLISH) | B38: 1.331 | C38: 1.346 | D38: 1.343
A39: British Pound to U.S. Dollar
A40: CAD/USD (BULLISH) | B40: 0.722 | C40: 0.729 | D40: 0.726
...

Sheet Dec 23.2025
A1: INDEX | B1: BUY TRADE | C1: SELL TRADE | D1: PREV. CLOSE
A2: UST30Y (BULLISH) | B2: 4.87 | C2: 4.77 | D2: 4.84
A3: 30-Year U.S. Treasury Yield
A4: UST10Y (BEARISH) | B4: 4.2 | C4: 4.1 | D4: 4.16
A5: 10-Year U.S. Treasury Yield
A6: UST2Y (BEARISH) | B6: 3.55 | C6: 3.44 | D6: 3.52
A7: 2-Year U.S. Treasury Yield
A8: HYG (BULLISH) | B8: 80.15 | C8: 80.68 | D8: 80.43
A9: High Yield
A10: LQD (BULLISH) | B10: 109.7 | C10: 110.8 | D10: 110.1
A11: Investment Grade Corporate Bond ETF
A12: SPX (BULLISH) | B12: 6751 | C12: 6945 | D12: 6878
A13: S&P 500
A14: COMPQ (BULLISH) | B14: 22667 | C14: 23851 | D14: 23428
A15: NASDAQ Composite
A16: RUT (BULLISH) | B16: 2511 | C16: 2612 | D16: 2558
A17: Russell 2000
A18: XLK (BULLISH) | B18: 140 | C18: 149 | D18: 145
A19: Technology Select Sector SPDR Fund
A20: XLV (BULLISH) | B20: 152 | C20: 157 | D20: 155
A21: Health Care Select Sector SPDR Fund
A22: XLY (BULLISH) | B22: 120 | C22: 124 | D22: 122
A23: Consumer Discretionary Select Sector SPDR Fund
A24: SSEC (NEUTRAL) | B24: 3824 | C24: 3931 | D24: 3919
A25: Shanghai Composite
A26: NIKK (BULLISH) | B26: 49003 | C26: 51197 | D26: 50412
A27: Nikkei 225 Index
A28: DAX (BULLISH) | B28: 23914 | C28: 24443 | D28: 24283
A29: German DAX Composite
A30: VIX (BEARISH) | B30: 13.67 | C30: 17.16 | D30: 14.08
A31: Volatility Index
A32: USD (BEARISH) | B32: 97.61 | C32: 98.6 | D32: 97.88
A33: U.S. Dollar Index
A34: EUR/USD (BULLISH) | B34: 1.169 | C34: 1.182 | D34: 1.18
A35: Euro to U.S. Dollar
A36: USD/YEN (BULLISH) | B36: 154.98 | C36: 157.76 | D36: 155.97
A37: U.S. Dollar to Japanese Yen
A38: GBP/USD (BULLISH) | B38: 1.332 | C38: 1.352 | D38: 1.351
A39: British Pound to U.S. Dollar
A40: CAD/USD (BULLISH) | B40: 0.724 | C40: 0.731 | D40: 0.729
...

Sheet Dec. 24.2025
A1: INDEX | B1: BUY TRADE | C1: SELL TRADE | D1: PREV. CLOSE
A2: UST30Y (BULLISH) | B2: 4.86 | C2: 4.78 | D2: 4.83
A3: 30-Year U.S. Treasury Yield
A4: UST10Y (BEARISH) | B4: 4.19 | C4: 4.11 | D4: 4.17
A5: 10-Year U.S. Treasury Yield
A6: UST2Y (BEARISH) | B6: 3.55 | C6: 3.43 | D6: 3.54
A7: 2-Year U.S. Treasury Yield
A8: HYG (BULLISH) | B8: 80.16 | C8: 80.67 | D8: 80.49
A9: High Yield
A10: LQD (BULLISH) | B10: 109.8 | C10: 110.7 | D10: 110.2
A11: Investment Grade Corporate Bond ETF
A12: SPX (BULLISH) | B12: 6803 | C12: 6954 | D12: 6909
A13: S&P 500
A14: COMPQ (BULLISH) | B14: 22771 | C14: 23852 | D14: 23561
A15: NASDAQ Composite
A16: RUT (BULLISH) | B16: 2501 | C16: 2603 | D16: 2541
A17: Russell 2000
A18: XLK (BULLISH) | B18: 140 | C18: 148 | D18: 146
A19: Technology Select Sector SPDR Fund
A20: XLV (BULLISH) | B20: 152 | C20: 157 | D20: 155
A21: Health Care Select Sector SPDR Fund
A22: XLY (BULLISH) | B22: 120 | C22: 124 | D22: 122
A23: Consumer Discretionary Select Sector SPDR Fund
A24: SSEC (NEUTRAL) | B24: 3826 | C24: 3964 | D24: 3940
A25: Shanghai Composite
A26: NIKK (BULLISH) | B26: 49005 | C26: 51165 | D26: 50344
A27: Nikkei 225 Index
A28: DAX (BULLISH) | B28: 24019 | C28: 24490 | D28: 24340
A29: German DAX Composite
A30: VIX (BEARISH) | B30: 13.15 | C30: 16.94 | D30: 14
A31: Volatility Index
A32: USD (BEARISH) | B32: 97.65 | C32: 98.59 | D32: 97.89
A33: U.S. Dollar Index
A34: EUR/USD (BULLISH) | B34: 1.171 | C34: 1.183 | D34: 1.179
A35: Euro to U.S. Dollar
A36: USD/YEN (BULLISH) | B36: 154.77 | C36: 157.68 | D36: 155.93
A37: U.S. Dollar to Japanese Yen
A38: GBP/USD (BULLISH) | B38: 1.334 | C38: 1.355 | D38: 1.351
A39: British Pound to U.S. Dollar
A40: CAD/USD (BULLISH) | B40: 0.724 | C40: 0.732 | D40: 0.731
...

Sheet Dec 26. 2025
A1: INDEX | B1: BUY TRADE | C1: SELL TRADE | D1: PREV. CLOSE
A2: UST30Y (BULLISH) | B2: 4.85 | C2: 4.78 | D2: 4.8
A3: 30-Year U.S. Treasury Yield
A4: UST10Y (BEARISH) | B4: 4.19 | C4: 4.1 | D4: 4.14
A5: 10-Year U.S. Treasury Yield
A6: UST2Y (BEARISH) | B6: 3.54 | C6: 3.46 | D6: 3.51
A7: 2-Year U.S. Treasury Yield
A8: HYG (BULLISH) | B8: 80.18 | C8: 80.79 | D8: 80.64
A9: High Yield
A10: LQD (BULLISH) | B10: 109.9 | C10: 110.8 | D10: 110.7
A11: Investment Grade Corporate Bond ETF
A12: SPX (BULLISH) | B12: 6817 | C12: 6974 | D12: 6932
A13: S&P 500
A14: COMPQ (BULLISH) | B14: 22711 | C14: 23799 | D14: 23613
A15: NASDAQ Composite
A16: RUT (BULLISH) | B16: 2507 | C16: 2601 | D16: 2548
A17: Russell 2000
A18: XLK (BULLISH) | B18: 140 | C18: 149 | D18: 146
A19: Technology Select Sector SPDR Fund
A20: XLV (BULLISH) | B20: 152 | C20: 158 | D20: 156
A21: Health Care Select Sector SPDR Fund
A22: XLY (BULLISH) | B22: 121 | C22: 124 | D22: 123
A23: Consumer Discretionary Select Sector SPDR Fund
A24: SSEC (BULLISH) | B24: 3856 | C24: 3995 | D24: 3963
A25: Shanghai Composite
A26: NIKK (BULLISH) | B26: 49067 | C26: 51168 | D26: 50750
A27: Nikkei 225 Index
A28: DAX (BULLISH) | B28: 24021 | C28: 24474 | D28: 24340
A29: German DAX Composite
A30: VIX (BEARISH) | B30: 12.96 | C30: 16.61 | D30: 13.47
A31: Volatility Index
A32: USD (BEARISH) | B32: 97.61 | C32: 98.58 | D32: 98.04
A33: U.S. Dollar Index
A34: EUR/USD (BULLISH) | B34: 1.172 | C34: 1.182 | D34: 1.178
A35: Euro to U.S. Dollar
A36: USD/YEN (BULLISH) | B36: 154.79 | C36: 157.83 | D36: 156.43
A37: U.S. Dollar to Japanese Yen
A38: GBP/USD (BULLISH) | B38: 1.336 | C38: 1.357 | D38: 1.349
A39: British Pound to U.S. Dollar
A40: CAD/USD (BULLISH) | B40: 0.724 | C40: 0.734 | D40: 0.73
...

Sheet Dec 29. 2025
A1: INDEX | B1: BUY TRADE | C1: SELL TRADE | D1: PREV. CLOSE
A2: UST30Y (BULLISH) | B2: 4.85 | C2: 4.76 | D2: 4.83
A3: 30-Year U.S. Treasury Yield
A4: UST10Y (BEARISH) | B4: 4.18 | C4: 4.09 | D4: 4.14
A5: 10-Year U.S. Treasury Yield
A6: UST2Y (BEARISH) | B6: 3.53 | C6: 3.44 | D6: 3.48
A7: 2-Year U.S. Treasury Yield
A8: HYG (BULLISH) | B8: 80.21 | C8: 80.82 | D8: 80.6
A9: High Yield
A10: LQD (BULLISH) | B10: 109.8 | C10: 111.1 | D10: 110.6
A11: Investment Grade Corporate Bond ETF
A12: SPX (BULLISH) | B12: 6826 | C12: 6986 | D12: 6929
A13: S&P 500
A14: COMPQ (BULLISH) | B14: 22741 | C14: 23892 | D14: 23593
A15: NASDAQ Composite
A16: RUT (BULLISH) | B16: 2504 | C16: 2577 | D16: 2534
A17: Russell 2000
A18: XLK (BULLISH) | B18: 140 | C18: 149 | D18: 147
A19: Technology Select Sector SPDR Fund
A20: XLV (BULLISH) | B20: 152 | C20: 158 | D20: 156
A21: Health Care Select Sector SPDR Fund
A22: XLY (BULLISH) | B22: 121 | C22: 124 | D22: 122
A23: Consumer Discretionary Select Sector SPDR Fund
A24: SSEC (BULLISH) | B24: 3858 | C24: 3999 | D24: 3965
A25: Shanghai Composite
A26: NIKK (BULLISH) | B26: 49069 | C26: 51178 | D26: 50526
A27: Nikkei 225 Index
A28: DAX (BULLISH) | B28: 24019 | C28: 24471 | D28: 24340
A29: German DAX Composite
A30: VIX (BEARISH) | B30: 12.18 | C30: 16.37 | D30: 13.6
A31: Volatility Index
A32: USD (BEARISH) | B32: 97.64 | C32: 98.61 | D32: 98.14
A33: U.S. Dollar Index
A34: EUR/USD (BULLISH) | B34: 1.171 | C34: 1.182 | D34: 1.176
A35: Euro to U.S. Dollar
A36: USD/YEN (BULLISH) | B36: 154.85 | C36: 157.76 | D36: 156.35
A37: U.S. Dollar to Japanese Yen
A38: GBP/USD (BULLISH) | B38: 1.336 | C38: 1.357 | D38: 1.348
A39: British Pound to U.S. Dollar
A40: CAD/USD (BULLISH) | B40: 0.725 | C40: 0.735 | D40: 0.73
...

Sheet Dec 30. 2025
A1: INDEX | B1: BUY TRADE | C1: SELL TRADE | D1: PREV. CLOSE
A2: UST30Y (BULLISH) | B2: 4.84 | C2: 4.76 | D2: 4.8
A3: 30-Year U.S. Treasury Yield
A4: UST10Y (BEARISH) | B4: 4.17 | C4: 4.07 | D4: 4.11
A5: 10-Year U.S. Treasury Yield
A6: UST2Y (BEARISH) | B6: 3.52 | C6: 3.43 | D6: 3.44
A7: 2-Year U.S. Treasury Yield
A8: HYG (BULLISH) | B8: 80.29 | C8: 80.85 | D8: 80.63
A9: High Yield
A10: LQD (BULLISH) | B10: 109.9 | C10: 111.2 | D10: 110.8
A11: Investment Grade Corporate Bond ETF
A12: SPX (BULLISH) | B12: 6831 | C12: 6998 | D12: 6905
A13: S&P 500
A14: COMPQ (BULLISH) | B14: 22759 | C14: 23912 | D14: 23474
A15: NASDAQ Composite
A16: RUT (BULLISH) | B16: 2501 | C16: 2587 | D16: 2519
A17: Russell 2000
A18: XLK (BULLISH) | B18: 141 | C18: 150 | D18: 146
A19: Technology Select Sector SPDR Fund
A20: XLV (BULLISH) | B20: 153 | C20: 158 | D20: 156
A21: Health Care Select Sector SPDR Fund
A22: XLY (BULLISH) | B22: 120 | C22: 124 | D22: 121
A23: Consumer Discretionary Select Sector SPDR Fund
A24: SSEC (BULLISH) | B24: 3861 | C24: 3996 | D24: 3965
A25: Shanghai Composite
A26: NIKK (BULLISH) | B26: 49061 | C26: 51212 | D26: 50339
A27: Nikkei 225 Index
A28: DAX (BULLISH) | B28: 24022 | C28: 24472 | D28: 24351
A29: German DAX Composite
A30: VIX (BEARISH) | B30: 12.11 | C30: 17.15 | D30: 14.2
A31: Volatility Index
A32: USD (BEARISH) | B32: 97.57 | C32: 98.54 | D32: 98.08
A33: U.S. Dollar Index
A34: EUR/USD (BULLISH) | B34: 1.171 | C34: 1.182 | D34: 1.176
A35: Euro to U.S. Dollar
A36: USD/YEN (BULLISH) | B36: 154.99 | C36: 157.68 | D36: 155.99
A37: U.S. Dollar to Japanese Yen
A38: GBP/USD (BULLISH) | B38: 1.338 | C38: 1.357 | D38: 1.35
A39: British Pound to U.S. Dollar
